package com.example.myapplication.jvm;

public class ExceptionFoo {
    private int tryBlock;
    private int catchBlock;
    private int finallyBlock;
    private int methodExit;

    public void test() {
        try {
            tryBlock = 0;
        } catch (Exception e) {
            catchBlock = 1;
        } finally {
            finallyBlock = 2;
        }
        methodExit = 3;
    }
}
/*
可以看到，编译结果包含三份 finally 代码块。
其中，前两份分别位于 try 代码块和 catch 代码块的正常执行路径出口。
最后一份则作为异常处理器，监控 try 代码块以及 catch 代码块。
它将捕获 try 代码块触发的、未被 catch 代码块捕获的异常，以及 catch 代码块触发的异常。
* $ javap -c Foo
...
  public void test();
    Code:
       0: aload_0
       1: iconst_0
       2: putfield      #20                 // Field tryBlock:I
       5: goto          30
       8: astore_1
       9: aload_0
      10: iconst_1
      11: putfield      #22                 // Field catchBlock:I
      14: aload_0
      15: iconst_2
      16: putfield      #24                 // Field finallyBlock:I
      19: goto          35
      22: astore_2
      23: aload_0
      24: iconst_2
      25: putfield      #24                 // Field finallyBlock:I
      28: aload_2
      29: athrow
      30: aload_0
      31: iconst_2
      32: putfield      #24                 // Field finallyBlock:I
      35: aload_0
      36: iconst_3
      37: putfield      #26                 // Field methodExit:I
      40: return
    Exception table:
       from    to  target type
           0     5     8   Class java/lang/Exception
           0    14    22   any

  ...

* */
